<?xml version="1.0"?>
<robot name="physics">


 <!--                                  LINK 0                                   -->
  <link name="link0">
    <visual name='link0_visual'>
        <origin rpy="0 0 0" xyz="0.0 .28 0"/>

        <geometry>
            <mesh filename="package://meshes/mist_mainwing.STL" scale="0.001 0.001 0.001"/>
        </geometry>
      <material name="white">
        <color rgba="1 1 1 1"/>
      </material>
    </visual>
    
    <collision name='link0_collision'>
        <origin rpy="0 0 0" xyz="0 0 -.15 "/>
        <geometry>
            <box size="0.7 0.7 0.1"/>
        </geometry>
    </collision>
    
    <inertial>
      <mass value="20"/>
      <inertia ixx="1.0" ixy="0.0" ixz="0.0" iyy="1.0" iyz="0.0" izz="1.0"/>
    </inertial>
  </link>
 <!--                                  LINK 1                                   -->
 <link name="link1">
    <visual name='link1_visual'>
        <origin rpy="0 0 0" xyz="0.0 .28 0"/>

        <geometry>
            <mesh filename="package://meshes/mist_mainwing.STL" scale="0.001 0.001 0.001"/>
        </geometry>

      <material name="blue">
        <color rgba="0 0 .8 1"/>
      </material>
    </visual>
    
    <collision name='link1_collision'>
        <origin rpy="0 0 0" xyz="0 0 -.15 "/>

        <geometry>
            <box size="0.7 0.7 0.1"/>
        </geometry>
    </collision>
    
    <inertial>
      <mass value="20"/>
      <inertia ixx="1.0" ixy="0.0" ixz="0.0" iyy="1.0" iyz="0.0" izz="1.0"/>
    </inertial>
  </link>


   <!--                                  LINK 2                                  -->
 <link name="link2">
    <visual name='link2_visual'>
        <origin rpy="0 0 0" xyz="0.0 .28 0"/>

        <geometry>
            <mesh filename="package://meshes/mist_mainwing.STL" scale="0.001 0.001 0.001"/>
        </geometry>
    </visual>
    
    <collision name='link2_collision'>
        <origin rpy="0 0 0" xyz="0 0 -.15 "/>

        <geometry>
            <box size="0.7 0.7 0.1"/>
        </geometry>
    </collision>
    
    <inertial>
      <mass value="20"/>
      <inertia ixx="1.0" ixy="0.0" ixz="0.0" iyy="1.0" iyz="0.0" izz="1.0"/>
    </inertial>
  </link>

     <!--                                  LINK 3                                  -->
 <link name="link3">
    <visual name='link3_visual'>
        <origin rpy="0 0 0" xyz="0.0 .28 0"/>

        <geometry>
            <mesh filename="package://meshes/mist_mainwing.STL" scale="0.001 0.001 0.001"/>
        </geometry>
    </visual>
    
    <collision name='link3_collision'>
        <origin rpy="0 0 0" xyz="0 0 -.15 "/>

        <geometry>
            <box size="0.7 0.7 0.1"/>
        </geometry>
    </collision>
    
    <inertial>
      <mass value="20"/>
      <inertia ixx="1.0" ixy="0.0" ixz="0.0" iyy="1.0" iyz="0.0" izz="1.0"/>
    </inertial>
  </link>


    <joint name="h0_joint" type="revolute">
    <axis xyz="0 0 1"/>
    <parent link="link1"/>
    <child link="link0"/>
    <origin rpy="0 0 0" xyz="0 .58 0"/>
    <limit effort="10" velocity="10" lower="0" upper="1.57079632679"/>
    <joint_properties damping="1.0" friction="0.0"/>
  </joint>

      <joint name="h1_joint" type="revolute">
    <axis xyz="0 0 1"/>
    <parent link="link2"/>
    <child link="link1"/>
    <origin rpy="0 0 0" xyz="0 .58 0"/>
    <limit effort="10" velocity="10" lower="0" upper="1.57079632679"/>
    <joint_properties damping="1.0" friction="0.0"/>
  </joint>

        <joint name="h2_joint" type="revolute">
    <axis xyz="0 0 1"/>
    <parent link="link3"/>
    <child link="link2"/>
    <origin rpy="0 0 0" xyz="0 .58 0"/>
    <limit effort="10" velocity="10" lower="0" upper="1.57079632679"/>
    <joint_properties damping="1.0" friction="0.0"/>
  </joint>



</robot>