<?xml version="1.0"?>
<robot name="physics">


 <!--                                  LINK 0                                   -->
  <link name="link0">
    <visual name='link0_visual'>
        <origin rpy="0 0 0" xyz="0.0 .28 0"/>

        <geometry>
            <mesh filename="package://meshes/mist_mainwing.STL" scale="0.001 0.001 0.001"/>
        </geometry>
      <material name="white">
        <color rgba="1 1 1 1"/>
      </material>
    </visual>
    
    <collision name='link0_collision'>
        <origin rpy="0 0 0" xyz="0 0 -.2 "/>
        <geometry>
            <box size="0.7 0.7 0.1"/>
        </geometry>
    </collision>
    
    <inertial>
      <mass value="20"/>
      <inertia ixx="1.0" ixy="0.0" ixz="0.0" iyy="1.0" iyz="0.0" izz="1.0"/>
    </inertial>
  </link>
 <!--                                  LINK 1                                   -->
 <link name="link1">
    <visual name='link1_visual'>
        <origin rpy="0 0 0" xyz="0.0 .28 0"/>

        <geometry>
            <mesh filename="package://meshes/mist_mainwing.STL" scale="0.001 0.001 0.001"/>
        </geometry>

      <material name="blue">
        <color rgba="0 0 .8 1"/>
      </material>
    </visual>
    
    <collision name='link1_collision'>
        <origin rpy="0 0 0" xyz="0 0 -.2 "/>

        <geometry>
            <box size="0.7 0.7 0.1"/>
        </geometry>
    </collision>
    
    <inertial>
      <mass value="20"/>
      <inertia ixx="1.0" ixy="0.0" ixz="0.0" iyy="1.0" iyz="0.0" izz="1.0"/>
    </inertial>
  </link>


   <!--                                  LINK 2                                  -->
 <link name="link2">
    <visual name='link2_visual'>
        <origin rpy="0 0 0" xyz="0.0 .28 0"/>

        <geometry>
            <mesh filename="package://meshes/mist_mainwing.STL" scale="0.001 0.001 0.001"/>
        </geometry>
      
      <material name="green">
        <color rgba="0 1 0 1"/>
      </material>
    </visual>
    
    <collision name='link2_collision'>
        <origin rpy="0 0 0" xyz="0 0 -.2 "/>

        <geometry>
            <box size="0.7 0.7 0.1"/>
        </geometry>
    </collision>
    
    <inertial>
      <mass value="20"/>
      <inertia ixx="1.0" ixy="0.0" ixz="0.0" iyy="1.0" iyz="0.0" izz="1.0"/>
    </inertial>
  </link>

     <!--                                  LINK 3                                  -->
 <link name="link3">
    <visual name='link3_visual'>
        <origin rpy="0 0 0" xyz="0.0 .28 0"/>

        <geometry>
            <mesh filename="package://meshes/mist_mainwing.STL" scale="0.001 0.001 0.001"/>
        </geometry>

      <material name="red">
        <color rgba="1 0 0 1"/>
      </material>
    </visual>
    
    <collision name='link3_collision'>
        <origin rpy="0 0 0" xyz="0 0 -.2 "/>

        <geometry>
            <box size="0.7 0.7 0.1"/>
        </geometry>
    </collision>
    
    <inertial>
      <mass value="20"/>
      <inertia ixx="1.0" ixy="0.0" ixz="0.0" iyy="1.0" iyz="0.0" izz="1.0"/>
    </inertial>
  </link>


    <joint name="h0_joint" type="revolute">
    <axis xyz="0 0 1"/>
    <parent link="link1"/>
    <child link="link0"/>
    <origin rpy="0 0 0" xyz="0 .58 0"/>
    <limit effort="1" velocity="1" lower="0" upper="1.57079632679"/>
    <joint_properties damping="1.0" friction="0.0"/>
  </joint>

      <joint name="h1_joint" type="revolute">
    <axis xyz="0 0 1"/>
    <parent link="link2"/>
    <child link="link1"/>
    <origin rpy="0 0 0" xyz="0 .58 0"/>
    <limit effort="1" velocity="1" lower="0" upper="1.57079632679"/>
    <joint_properties damping="1.0" friction="0.0"/>
  </joint>

        <joint name="h2_joint" type="revolute">
    <axis xyz="0 0 1"/>
    <parent link="link3"/>
    <child link="link2"/>
    <origin rpy="0 0 0" xyz="0 .58 0"/>
    <limit effort="1" velocity="1" lower="0" upper="1.57079632679"/>
    <joint_properties damping="1.0" friction="0.0"/>
  </joint>





<!--                              control surface 0                       -->
  <link name="ctrlsurf0">
    <visual name='ctrlsurf0_visual'>
        <origin rpy="0 0 0" xyz="0.0 .28 -.05"/>

        <geometry>
            <mesh filename="package://meshes/mist_controlsurface.STL" scale="0.001 0.001 0.001"/>
        </geometry>
      <material name="white">
        <color rgba="1 1 1 1"/>
      </material>
    </visual>
    
    <inertial>
      <mass value="20"/>
      <inertia ixx="1.0" ixy="0.0" ixz="0.0" iyy="1.0" iyz="0.0" izz="1.0"/>
    </inertial>
  </link>


  <!--                              control surface 1                       -->
  <link name="ctrlsurf1">
    <visual name='ctrlsurf1_visual'>
        <origin rpy="0 0 0" xyz="0.0 .28 -.05"/>

        <geometry>
            <mesh filename="package://meshes/mist_controlsurface.STL" scale="0.001 0.001 0.001"/>
        </geometry>
      <material name="white">
      </material>
    </visual>
    
    <inertial>
      <mass value="20"/>
      <inertia ixx="1.0" ixy="0.0" ixz="0.0" iyy="1.0" iyz="0.0" izz="1.0"/>
    </inertial>
  </link>


  <!--                              control surface 2                       -->
  <link name="ctrlsurf2">
    <visual name='ctrlsurf2_visual'>
        <origin rpy="0 0 0" xyz="0.0 .28 -.05"/>

        <geometry>
            <mesh filename="package://meshes/mist_controlsurface.STL" scale="0.001 0.001 0.001"/>
        </geometry>
      <material name="white">
      </material>
    </visual>
    
    <inertial>
      <mass value="20"/>
      <inertia ixx="1.0" ixy="0.0" ixz="0.0" iyy="1.0" iyz="0.0" izz="1.0"/>
    </inertial>
  </link>


  <!--                              control surface 3                       -->
  <link name="ctrlsurf3">
    <visual name='ctrlsurf3_visual'>
        <origin rpy="0 0 0" xyz="0.0 .28 -.05"/>

        <geometry>
            <mesh filename="package://meshes/mist_controlsurface.STL" scale="0.001 0.001 0.001"/>
        </geometry>
      <material name="white">
      </material>
    </visual>
    
    <inertial>
      <mass value="20"/>
      <inertia ixx="1.0" ixy="0.0" ixz="0.0" iyy="1.0" iyz="0.0" izz="1.0"/>
    </inertial>
  </link>

  <joint name="link0_ctrlsurf0" type="revolute">
    <axis xyz="0 1 0"/>
    <parent link="link0"/>
    <child link="ctrlsurf0"/>
    <origin rpy="0 0 0" xyz="-.003 0 -.08"/>
    <limit effort="1" velocity="1" lower="-1.57079632679" upper="1.57079632679"/>
    <joint_properties damping="1.0" friction="0.0"/>
  </joint>

  <joint name="link1_ctrlsurf1" type="revolute">
    <axis xyz="0 1 0"/>
    <parent link="link1"/>
    <child link="ctrlsurf1"/>
    <origin rpy="0 0 0" xyz="-.003 0 -.08"/>
    <limit effort="1" velocity="1" lower="-1.57079632679" upper="1.57079632679"/>
    <joint_properties damping="1.0" friction="0.0"/>
  </joint>


  <joint name="link2_ctrlsurf2" type="revolute">
    <axis xyz="0 1 0"/>
    <parent link="link2"/>
    <child link="ctrlsurf2"/>
    <origin rpy="0 0 0" xyz="-.003 0 -.08"/>
    <limit effort="1" velocity="1" lower="-1.57079632679" upper="1.57079632679"/>
    <joint_properties damping="1.0" friction="0.0"/>
  </joint>

  <joint name="link3_ctrlsurf3" type="revolute">
    <axis xyz="0 1 0"/>
    <parent link="link3"/>
    <child link="ctrlsurf3"/>
    <origin rpy="0 0 0" xyz="-.003 0 -.08"/>
    <limit effort="1" velocity="1" lower="-1.57079632679" upper="1.57079632679"/>
    <joint_properties damping="1.0" friction="0.0"/>
  </joint>

<!--                               Propeller 0                             -->
<link name="prop0">
    <visual name='prop0_visual'>
        <origin rpy="0 0 0" xyz="0.0 .28 -.05"/>

        <geometry>
            <mesh filename="package://meshes/propeller_ccw.dae" scale="0.1 0.1 0.1"/>
        </geometry>
      <material name="blue">
      </material>
    </visual>
    
    <inertial>
      <mass value=".1"/>
      <inertia ixx="1.0" ixy="0.0" ixz="0.0" iyy="1.0" iyz="0.0" izz="1.0"/>
    </inertial>
  </link>

<!--                               Propeller 1                             -->
<link name="prop1">
    <visual name='prop1_visual'>
        <origin rpy="0 0 0" xyz="0.0 .28 -.05"/>

        <geometry>
            <mesh filename="package://meshes/propeller_ccw.dae" scale="0.1 0.1 0.1"/>
        </geometry>
      <material name="blue">
      </material>
    </visual>
    
    <inertial>
      <mass value=".1"/>
      <inertia ixx="1.0" ixy="0.0" ixz="0.0" iyy="1.0" iyz="0.0" izz="1.0"/>
    </inertial>
  </link>


  <!--                               Propeller 2                             -->
<link name="prop2">
    <visual name='prop2_visual'>
        <origin rpy="0 0 0" xyz="0.0 .28 -.05"/>

        <geometry>
            <mesh filename="package://meshes/propeller_ccw.dae" scale="0.1 0.1 0.1"/>
        </geometry>
      <material name="blue">
      </material>
    </visual>
    
    <inertial>
      <mass value=".1"/>
      <inertia ixx="1.0" ixy="0.0" ixz="0.0" iyy="1.0" iyz="0.0" izz="1.0"/>
    </inertial>
  </link>



  <!--                               Propeller 3                             -->
<link name="prop3">
    <visual name='prop3_visual'>
        <origin rpy="0 0 0" xyz="0.0 .28 -.05"/>

        <geometry>
            <mesh filename="package://meshes/propeller_ccw.dae" scale="0.1 0.1 0.1"/>
        </geometry>
      <material name="blue">
      </material>
    </visual>
    
    <inertial>
      <mass value=".1"/>
      <inertia ixx="1.0" ixy="0.0" ixz="0.0" iyy="1.0" iyz="0.0" izz="1.0"/>
    </inertial>
  </link>



  <joint name="link0_prop0" type="continuous">
    <axis xyz="0 0 1"/>
    <parent link="link0"/>
    <child link="prop0"/>
    <origin rpy="0 0 0" xyz="-.003 0 .185"/>
    <limit effort="1" velocity="1" lower="-1.57079632679" upper="1.57079632679"/>
    <joint_properties damping="1.0" friction="0.0"/>
  </joint>

  <joint name="link1_prop1" type="continuous">
    <axis xyz="0 0 1"/>
    <parent link="link1"/>
    <child link="prop1"/>
    <origin rpy="0 0 0" xyz="-.003 0 .185"/>
    <limit effort="1" velocity="1" lower="-1.57079632679" upper="1.57079632679"/>
    <joint_properties damping="1.0" friction="0.0"/>
  </joint>

  <joint name="link2_prop2" type="continuous">
    <axis xyz="0 0 1"/>
    <parent link="link2"/>
    <child link="prop2"/>
    <origin rpy="0 0 0" xyz="-.003 0 .185"/>
    <limit effort="1" velocity="1" lower="-1.57079632679" upper="1.57079632679"/>
    <joint_properties damping="1.0" friction="0.0"/>
  </joint>

  <joint name="link3_prop3" type="continuous">
    <axis xyz="0 0 1"/>
    <parent link="link3"/>
    <child link="prop3"/>
    <origin rpy="0 0 0" xyz="-.003 0 .185"/>
    <limit effort="1" velocity="1" lower="-1.57079632679" upper="1.57079632679"/>
    <joint_properties damping="1.0" friction="0.0"/>
  </joint>





</robot>